<robot name = "robot">
    <link name="Torso">
        <inertial>
            <origin xyz="0 0 4.0" rpy="0 0 0"/>
            <mass value="1" />
            <inertia ixx="100" ixy="0" ixz="0" iyy="100" iyz="0" izz="100" />
        </inertial>
        <visual>
            <origin xyz="0 0 4.0" rpy="0 0 0"/>
            <geometry>
                <box size="2.102588988568354 0.8811156256775701 0.7102290858942212" />
            </geometry>
            <material name="Green">
                <color rgba="0 1.0 0.0 1.0"/>
            </material>
        </visual>
        <collision>
            <origin xyz="0 0 4.0" rpy="0 0 0"/>
            <geometry>
                <box size="2.102588988568354 0.8811156256775701 0.7102290858942212" />
            </geometry>
        </collision>
    </link>
    <joint name="Torso_0" type="revolute">
       <parent link="Torso"/>
       <child  link="0"/>
       <origin rpy="0 0 0" xyz="0 0 3.6448854570528892" />
     <axis xyz="0 1 0"/>
       <limit effort="0.0" lower="-3.14159" upper="3.14159" velocity="0.0"/>
    </joint>
    <link name="0">
        <inertial>
            <origin xyz="0 0.44055781283878503 -0.2863017535699113" rpy="0 0 0"/>
            <mass value="1" />
            <inertia ixx="100" ixy="0" ixz="0" iyy="100" iyz="0" izz="100" />
        </inertial>
        <visual>
            <origin xyz="0 0.44055781283878503 -0.2863017535699113" rpy="0 0 0"/>
            <geometry>
                <box size="1.051294494284177 0.44055781283878503 0.5726035071398226" />
            </geometry>
            <material name="Green">
                <color rgba="0 1.0 0.0 1.0"/>
            </material>
        </visual>
        <collision>
            <origin xyz="0 0.44055781283878503 -0.2863017535699113" rpy="0 0 0"/>
            <geometry>
                <box size="1.051294494284177 0.44055781283878503 0.5726035071398226" />
            </geometry>
        </collision>
    </link>
    <joint name="Torso_1" type="revolute">
       <parent link="Torso"/>
       <child  link="1"/>
       <origin rpy="0 0 0" xyz="0 0 3.6448854570528892" />
     <axis xyz="0 1 0"/>
       <limit effort="0.0" lower="-3.14159" upper="3.14159" velocity="0.0"/>
    </joint>
    <link name="1">
        <inertial>
            <origin xyz="0 -0.44055781283878503 -0.2863017535699113" rpy="0 0 0"/>
            <mass value="1" />
            <inertia ixx="100" ixy="0" ixz="0" iyy="100" iyz="0" izz="100" />
        </inertial>
        <visual>
            <origin xyz="0 -0.44055781283878503 -0.2863017535699113" rpy="0 0 0"/>
            <geometry>
                <box size="1.051294494284177 0.44055781283878503 0.5726035071398226" />
            </geometry>
            <material name="Blue">
                <color rgba="0 0.0 1.0 1.0"/>
            </material>
        </visual>
        <collision>
            <origin xyz="0 -0.44055781283878503 -0.2863017535699113" rpy="0 0 0"/>
            <geometry>
                <box size="1.051294494284177 0.44055781283878503 0.5726035071398226" />
            </geometry>
        </collision>
    </link>
    <joint name="Torso_2" type="revolute">
       <parent link="Torso"/>
       <child  link="2"/>
       <origin rpy="0 0 0" xyz="1.051294494284177 0 4.0" />
     <axis xyz="0 1 0"/>
       <limit effort="0.0" lower="-3.14159" upper="3.14159" velocity="0.0"/>
    </joint>
    <link name="2">
        <inertial>
            <origin xyz="0.555324233916653 0 0" rpy="0 0 0"/>
            <mass value="1" />
            <inertia ixx="100" ixy="0" ixz="0" iyy="100" iyz="0" izz="100" />
        </inertial>
        <visual>
            <origin xyz="0.555324233916653 0 0" rpy="0 0 0"/>
            <geometry>
                <box size="1.110648467833306 0.6687621758201829 2.7446895863071648" />
            </geometry>
            <material name="Blue">
                <color rgba="0 0.0 1.0 1.0"/>
            </material>
        </visual>
        <collision>
            <origin xyz="0.555324233916653 0 0" rpy="0 0 0"/>
            <geometry>
                <box size="1.110648467833306 0.6687621758201829 2.7446895863071648" />
            </geometry>
        </collision>
    </link>
    <joint name="2_3" type="revolute">
       <parent link="2"/>
       <child  link="3"/>
       <origin rpy="0 0 0" xyz="0.555324233916653 0.33438108791009147 -1.3723447931535824" />
     <axis xyz="0 1 0"/>
       <limit effort="0.0" lower="-3.14159" upper="3.14159" velocity="0.0"/>
    </joint>
    <link name="3">
        <inertial>
            <origin xyz="0 0 -0.24838068495330218" rpy="0 0 0"/>
            <mass value="1" />
            <inertia ixx="100" ixy="0" ixz="0" iyy="100" iyz="0" izz="100" />
        </inertial>
        <visual>
            <origin xyz="0 0 -0.24838068495330218" rpy="0 0 0"/>
            <geometry>
                <box size="0.555324233916653 0.33438108791009147 0.49676136990660436" />
            </geometry>
            <material name="Blue">
                <color rgba="0 0.0 1.0 1.0"/>
            </material>
        </visual>
        <collision>
            <origin xyz="0 0 -0.24838068495330218" rpy="0 0 0"/>
            <geometry>
                <box size="0.555324233916653 0.33438108791009147 0.49676136990660436" />
            </geometry>
        </collision>
    </link>
    <joint name="2_4" type="revolute">
       <parent link="2"/>
       <child  link="4"/>
       <origin rpy="0 0 0" xyz="0.555324233916653 -0.33438108791009147 -1.3723447931535824" />
     <axis xyz="0 1 0"/>
       <limit effort="0.0" lower="-3.14159" upper="3.14159" velocity="0.0"/>
    </joint>
    <link name="4">
        <inertial>
            <origin xyz="0 0 -0.24838068495330218" rpy="0 0 0"/>
            <mass value="1" />
            <inertia ixx="100" ixy="0" ixz="0" iyy="100" iyz="0" izz="100" />
        </inertial>
        <visual>
            <origin xyz="0 0 -0.24838068495330218" rpy="0 0 0"/>
            <geometry>
                <box size="0.555324233916653 0.33438108791009147 0.49676136990660436" />
            </geometry>
            <material name="Blue">
                <color rgba="0 0.0 1.0 1.0"/>
            </material>
        </visual>
        <collision>
            <origin xyz="0 0 -0.24838068495330218" rpy="0 0 0"/>
            <geometry>
                <box size="0.555324233916653 0.33438108791009147 0.49676136990660436" />
            </geometry>
        </collision>
    </link>
    <joint name="2_5" type="revolute">
       <parent link="2"/>
       <child  link="5"/>
       <origin rpy="0 0 0" xyz="1.110648467833306 0 0" />
     <axis xyz="0 1 0"/>
       <limit effort="0.0" lower="-3.14159" upper="3.14159" velocity="0.0"/>
    </joint>
    <link name="5">
        <inertial>
            <origin xyz="0.26996605472190977 0 0" rpy="0 0 0"/>
            <mass value="1" />
            <inertia ixx="100" ixy="0" ixz="0" iyy="100" iyz="0" izz="100" />
        </inertial>
        <visual>
            <origin xyz="0.26996605472190977 0 0" rpy="0 0 0"/>
            <geometry>
                <box size="0.5399321094438195 0.8681507699572628 2.5857090337321518" />
            </geometry>
            <material name="Green">
                <color rgba="0 1.0 0.0 1.0"/>
            </material>
        </visual>
        <collision>
            <origin xyz="0.26996605472190977 0 0" rpy="0 0 0"/>
            <geometry>
                <box size="0.5399321094438195 0.8681507699572628 2.5857090337321518" />
            </geometry>
        </collision>
    </link>
    <joint name="5_6" type="revolute">
       <parent link="5"/>
       <child  link="6"/>
       <origin rpy="0 0 0" xyz="0.26996605472190977 0.4340753849786314 -1.2928545168660759" />
     <axis xyz="0 1 0"/>
       <limit effort="0.0" lower="-3.14159" upper="3.14159" velocity="0.0"/>
    </joint>
    <link name="6">
        <inertial>
            <origin xyz="0 0 -1.288539517582115" rpy="0 0 0"/>
            <mass value="1" />
            <inertia ixx="100" ixy="0" ixz="0" iyy="100" iyz="0" izz="100" />
        </inertial>
        <visual>
            <origin xyz="0 0 -1.288539517582115" rpy="0 0 0"/>
            <geometry>
                <box size="0.26996605472190977 0.4340753849786314 2.57707903516423" />
            </geometry>
            <material name="Green">
                <color rgba="0 1.0 0.0 1.0"/>
            </material>
        </visual>
        <collision>
            <origin xyz="0 0 -1.288539517582115" rpy="0 0 0"/>
            <geometry>
                <box size="0.26996605472190977 0.4340753849786314 2.57707903516423" />
            </geometry>
        </collision>
    </link>
    <joint name="5_7" type="revolute">
       <parent link="5"/>
       <child  link="7"/>
       <origin rpy="0 0 0" xyz="0.26996605472190977 -0.4340753849786314 -1.2928545168660759" />
     <axis xyz="0 1 0"/>
       <limit effort="0.0" lower="-3.14159" upper="3.14159" velocity="0.0"/>
    </joint>
    <link name="7">
        <inertial>
            <origin xyz="0 0 -1.288539517582115" rpy="0 0 0"/>
            <mass value="1" />
            <inertia ixx="100" ixy="0" ixz="0" iyy="100" iyz="0" izz="100" />
        </inertial>
        <visual>
            <origin xyz="0 0 -1.288539517582115" rpy="0 0 0"/>
            <geometry>
                <box size="0.26996605472190977 0.4340753849786314 2.57707903516423" />
            </geometry>
            <material name="Green">
                <color rgba="0 1.0 0.0 1.0"/>
            </material>
        </visual>
        <collision>
            <origin xyz="0 0 -1.288539517582115" rpy="0 0 0"/>
            <geometry>
                <box size="0.26996605472190977 0.4340753849786314 2.57707903516423" />
            </geometry>
        </collision>
    </link>
    <joint name="5_8" type="revolute">
       <parent link="5"/>
       <child  link="8"/>
       <origin rpy="0 0 0" xyz="0.5399321094438195 0 0" />
     <axis xyz="0 1 0"/>
       <limit effort="0.0" lower="-3.14159" upper="3.14159" velocity="0.0"/>
    </joint>
    <link name="8">
        <inertial>
            <origin xyz="1.013995222066128 0 0" rpy="0 0 0"/>
            <mass value="1" />
            <inertia ixx="100" ixy="0" ixz="0" iyy="100" iyz="0" izz="100" />
        </inertial>
        <visual>
            <origin xyz="1.013995222066128 0 0" rpy="0 0 0"/>
            <geometry>
                <box size="2.027990444132256 2.685152673681337 0.6167452003274323" />
            </geometry>
            <material name="Blue">
                <color rgba="0 0.0 1.0 1.0"/>
            </material>
        </visual>
        <collision>
            <origin xyz="1.013995222066128 0 0" rpy="0 0 0"/>
            <geometry>
                <box size="2.027990444132256 2.685152673681337 0.6167452003274323" />
            </geometry>
        </collision>
    </link>
    <joint name="8_9" type="revolute">
       <parent link="8"/>
       <child  link="9"/>
       <origin rpy="0 0 0" xyz="1.013995222066128 1.3425763368406685 -0.30837260016371615" />
     <axis xyz="0 1 0"/>
       <limit effort="0.0" lower="-3.14159" upper="3.14159" velocity="0.0"/>
    </joint>
    <link name="9">
        <inertial>
            <origin xyz="0 0 -0.08381509328695086" rpy="0 0 0"/>
            <mass value="1" />
            <inertia ixx="100" ixy="0" ixz="0" iyy="100" iyz="0" izz="100" />
        </inertial>
        <visual>
            <origin xyz="0 0 -0.08381509328695086" rpy="0 0 0"/>
            <geometry>
                <box size="1.013995222066128 1.3425763368406685 0.16763018657390172" />
            </geometry>
            <material name="Blue">
                <color rgba="0 0.0 1.0 1.0"/>
            </material>
        </visual>
        <collision>
            <origin xyz="0 0 -0.08381509328695086" rpy="0 0 0"/>
            <geometry>
                <box size="1.013995222066128 1.3425763368406685 0.16763018657390172" />
            </geometry>
        </collision>
    </link>
    <joint name="8_10" type="revolute">
       <parent link="8"/>
       <child  link="10"/>
       <origin rpy="0 0 0" xyz="1.013995222066128 -1.3425763368406685 -0.30837260016371615" />
     <axis xyz="0 1 0"/>
       <limit effort="0.0" lower="-3.14159" upper="3.14159" velocity="0.0"/>
    </joint>
    <link name="10">
        <inertial>
            <origin xyz="0 0 -0.08381509328695086" rpy="0 0 0"/>
            <mass value="1" />
            <inertia ixx="100" ixy="0" ixz="0" iyy="100" iyz="0" izz="100" />
        </inertial>
        <visual>
            <origin xyz="0 0 -0.08381509328695086" rpy="0 0 0"/>
            <geometry>
                <box size="1.013995222066128 1.3425763368406685 0.16763018657390172" />
            </geometry>
            <material name="Blue">
                <color rgba="0 0.0 1.0 1.0"/>
            </material>
        </visual>
        <collision>
            <origin xyz="0 0 -0.08381509328695086" rpy="0 0 0"/>
            <geometry>
                <box size="1.013995222066128 1.3425763368406685 0.16763018657390172" />
            </geometry>
        </collision>
    </link>
    <joint name="8_11" type="revolute">
       <parent link="8"/>
       <child  link="11"/>
       <origin rpy="0 0 0" xyz="2.027990444132256 0 0" />
     <axis xyz="0 1 0"/>
       <limit effort="0.0" lower="-3.14159" upper="3.14159" velocity="0.0"/>
    </joint>
    <link name="11">
        <inertial>
            <origin xyz="0.25735400528885327 0 0" rpy="0 0 0"/>
            <mass value="1" />
            <inertia ixx="100" ixy="0" ixz="0" iyy="100" iyz="0" izz="100" />
        </inertial>
        <visual>
            <origin xyz="0.25735400528885327 0 0" rpy="0 0 0"/>
            <geometry>
                <box size="0.5147080105777065 2.0869413045412912 2.360772343590021" />
            </geometry>
            <material name="Blue">
                <color rgba="0 0.0 1.0 1.0"/>
            </material>
        </visual>
        <collision>
            <origin xyz="0.25735400528885327 0 0" rpy="0 0 0"/>
            <geometry>
                <box size="0.5147080105777065 2.0869413045412912 2.360772343590021" />
            </geometry>
        </collision>
    </link>
    <joint name="11_12" type="revolute">
       <parent link="11"/>
       <child  link="12"/>
       <origin rpy="0 0 0" xyz="0.25735400528885327 1.0434706522706456 -1.1803861717950106" />
     <axis xyz="0 1 0"/>
       <limit effort="0.0" lower="-3.14159" upper="3.14159" velocity="0.0"/>
    </joint>
    <link name="12">
        <inertial>
            <origin xyz="0 0 -0.5743202401939903" rpy="0 0 0"/>
            <mass value="1" />
            <inertia ixx="100" ixy="0" ixz="0" iyy="100" iyz="0" izz="100" />
        </inertial>
        <visual>
            <origin xyz="0 0 -0.5743202401939903" rpy="0 0 0"/>
            <geometry>
                <box size="0.25735400528885327 1.0434706522706456 1.1486404803879806" />
            </geometry>
            <material name="Blue">
                <color rgba="0 0.0 1.0 1.0"/>
            </material>
        </visual>
        <collision>
            <origin xyz="0 0 -0.5743202401939903" rpy="0 0 0"/>
            <geometry>
                <box size="0.25735400528885327 1.0434706522706456 1.1486404803879806" />
            </geometry>
        </collision>
    </link>
    <joint name="11_13" type="revolute">
       <parent link="11"/>
       <child  link="13"/>
       <origin rpy="0 0 0" xyz="0.25735400528885327 -1.0434706522706456 -1.1803861717950106" />
     <axis xyz="0 1 0"/>
       <limit effort="0.0" lower="-3.14159" upper="3.14159" velocity="0.0"/>
    </joint>
    <link name="13">
        <inertial>
            <origin xyz="0 0 -0.5743202401939903" rpy="0 0 0"/>
            <mass value="1" />
            <inertia ixx="100" ixy="0" ixz="0" iyy="100" iyz="0" izz="100" />
        </inertial>
        <visual>
            <origin xyz="0 0 -0.5743202401939903" rpy="0 0 0"/>
            <geometry>
                <box size="0.25735400528885327 1.0434706522706456 1.1486404803879806" />
            </geometry>
            <material name="Blue">
                <color rgba="0 0.0 1.0 1.0"/>
            </material>
        </visual>
        <collision>
            <origin xyz="0 0 -0.5743202401939903" rpy="0 0 0"/>
            <geometry>
                <box size="0.25735400528885327 1.0434706522706456 1.1486404803879806" />
            </geometry>
        </collision>
    </link>
    <joint name="11_14" type="revolute">
       <parent link="11"/>
       <child  link="14"/>
       <origin rpy="0 0 0" xyz="0.5147080105777065 0 0" />
     <axis xyz="0 1 0"/>
       <limit effort="0.0" lower="-3.14159" upper="3.14159" velocity="0.0"/>
    </joint>
    <link name="14">
        <inertial>
            <origin xyz="0.5906742197433424 0 0" rpy="0 0 0"/>
            <mass value="1" />
            <inertia ixx="100" ixy="0" ixz="0" iyy="100" iyz="0" izz="100" />
        </inertial>
        <visual>
            <origin xyz="0.5906742197433424 0 0" rpy="0 0 0"/>
            <geometry>
                <box size="1.1813484394866849 1.2198169778915595 0.9180615137273268" />
            </geometry>
            <material name="Blue">
                <color rgba="0 0.0 1.0 1.0"/>
            </material>
        </visual>
        <collision>
            <origin xyz="0.5906742197433424 0 0" rpy="0 0 0"/>
            <geometry>
                <box size="1.1813484394866849 1.2198169778915595 0.9180615137273268" />
            </geometry>
        </collision>
    </link>
    <joint name="14_15" type="revolute">
       <parent link="14"/>
       <child  link="15"/>
       <origin rpy="0 0 0" xyz="0.5906742197433424 0.6099084889457798 -0.4590307568636634" />
     <axis xyz="0 1 0"/>
       <limit effort="0.0" lower="-3.14159" upper="3.14159" velocity="0.0"/>
    </joint>
    <link name="15">
        <inertial>
            <origin xyz="0 0 -0.4237898107731167" rpy="0 0 0"/>
            <mass value="1" />
            <inertia ixx="100" ixy="0" ixz="0" iyy="100" iyz="0" izz="100" />
        </inertial>
        <visual>
            <origin xyz="0 0 -0.4237898107731167" rpy="0 0 0"/>
            <geometry>
                <box size="0.5906742197433424 0.6099084889457798 0.8475796215462335" />
            </geometry>
            <material name="Green">
                <color rgba="0 1.0 0.0 1.0"/>
            </material>
        </visual>
        <collision>
            <origin xyz="0 0 -0.4237898107731167" rpy="0 0 0"/>
            <geometry>
                <box size="0.5906742197433424 0.6099084889457798 0.8475796215462335" />
            </geometry>
        </collision>
    </link>
    <joint name="14_16" type="revolute">
       <parent link="14"/>
       <child  link="16"/>
       <origin rpy="0 0 0" xyz="0.5906742197433424 -0.6099084889457798 -0.4590307568636634" />
     <axis xyz="0 1 0"/>
       <limit effort="0.0" lower="-3.14159" upper="3.14159" velocity="0.0"/>
    </joint>
    <link name="16">
        <inertial>
            <origin xyz="0 0 -0.4237898107731167" rpy="0 0 0"/>
            <mass value="1" />
            <inertia ixx="100" ixy="0" ixz="0" iyy="100" iyz="0" izz="100" />
        </inertial>
        <visual>
            <origin xyz="0 0 -0.4237898107731167" rpy="0 0 0"/>
            <geometry>
                <box size="0.5906742197433424 0.6099084889457798 0.8475796215462335" />
            </geometry>
            <material name="Blue">
                <color rgba="0 0.0 1.0 1.0"/>
            </material>
        </visual>
        <collision>
            <origin xyz="0 0 -0.4237898107731167" rpy="0 0 0"/>
            <geometry>
                <box size="0.5906742197433424 0.6099084889457798 0.8475796215462335" />
            </geometry>
        </collision>
    </link>
</robot>